<?xml version="1.0" ?>
<!-- =================================================================================== -->
<!-- |    This document was autogenerated by xacro from /home/ras/jhm_ws/src/jaka_description/urdf/tracer_jaka_zu5.urdf.xacro | -->
<!-- |    EDITING THIS FILE BY HAND IS NOT RECOMMENDED                                 | -->
<!-- =================================================================================== -->
<robot name="tracer_jaka_zu5">
    <!-- <xacro:include filename="$(find tracer_description)/urdf/my_laser.urdf.xacro" /> -->
    <!-- <xacro:include filename="$(find tracer_description)/urdf/gazebo/laser.xacro" /> -->
    <!--0.37810-->
    <!--    <xacro:property name="track" value="0.3426" />
    <xacro:property name="wheelbase" value="0.3181"/>
    <xacro:property name="wheel_vertical_offset" value="-0.160000047342231" />-->
    <!-- Base link -->
    <link name="base_link">
        <visual>
            <origin rpy="1.57 0 0" xyz="0 0 0" />
            <!--<origin xyz="0 0 0" rpy="0 0 0"/>-->
            <geometry>
                <mesh filename="package://tracer_description/meshes/tracer_base_link_no_wheel.dae" />
                <!--<box size="${base_x_size} ${base_y_size} ${base_z_size}"/>-->
            </geometry>
        </visual>
        <collision>
            <!--origin
            xyz="-0.0145261552504705 0.0231316650320557 0.00586280190939592"
            rpy="0 0 0" /-->
            <origin rpy="1.57 0 0" xyz="0 0 0" />
            <geometry>
                <mesh filename="package://tracer_description/meshes/tracer_base_link_no_wheel.dae" />
                <!--<box size="${base_x_size} ${base_y_size} ${base_z_size}"/>-->
            </geometry>
        </collision>
        <inertial>
            <mass value="0.1" />
            <origin xyz="0 0 0" rpy="0 0 0" />
            <inertia ixx="0.03" iyy="0.03" izz="0.03" ixy="0.0" ixz="0.0" iyz="0.0" />
        </inertial>
    </link>
    <!-- <joint name="chassis_link_joint" type="fixed">
        <origin xyz="0 0 ${wheel_radius - wheel_vertical_offset}" rpy="0 0 0" />
        <parent link="base_link" />
        <child link="chassis_link" />
    </joint> -->
    <link name="inertial_link">
        <inertial>
            <!--mass value="44.3898489950015" /-->
            <mass value="132.3898489950015" />
            <!-- <mass value="50" /> -->
            <!-- <origin xyz="-0.00065 -0.085 0.062" />
            <inertia ixx="0.6022" ixy="-0.02364" ixz="-0.1197" iyy="1.7386" iyz="-0.001544" izz="2.0296" /> -->
            <origin xyz="0.015 0.0231316650320557 0" />
            <!--<origin
              xyz="-0.0145261552504705 0.0231316650320557 0.00586280190939592"
              rpy="0 0 0" />-->
            <inertia ixx="0.185196122711036" ixy="4.30144213829512E-08" ixz="5.81037523686401E-08" iyy="0.364893736238929" iyz="-0.000386720198091934" izz="0.223868521722778" />
            <!--<inertia ixx="2.288641" ixy="0" ixz="0" iyy="5.103976" iyz="0" izz="3.431465" />-->
        </inertial>
    </link>
    <joint name="inertial_joint" type="fixed">
        <origin rpy="0 0 0" xyz="0 0 0" />
        <parent link="base_link" />
        <child link="inertial_link" />
    </joint>
    <!-- For testing, hang the robot up in the air -->
    <!-- <link name="world" />
    <joint name="world_to_base_link=" type="fixed">
        <origin xyz="0 0 0.5" rpy="0 0 0" />
        <parent link="world"/>
        <child link="base_link"/>
    </joint> -->
    <link name="right_wheel_link">
        <!--<inertial>
                <mass value="3" />
                <origin
                        xyz="0.162297526351145 -0.159063056237197 -0.159999952657767"
                        rpy="0 0 0" />
                        <inertia ixx="0.7171" ixy="0" ixz="0" iyy="0.1361" iyz="0" izz="0.7171" />
                   </inertial>
            <visual>
                <origin xyz="0 0 0" rpy="0 0 0" />
                <geometry>
                    <mesh filename="package://tracer_description/meshes/wheel.dae" />
                </geometry>
            </visual>-->
        <inertial>
            <mass value="6" />
            <origin xyz="0 0 0" rpy="0 0 0" />
            <inertia ixx="0.7171" ixy="0" ixz="0" iyy="0.1361" iyz="0" izz="0.7171" />
            <!--<inertia ixx="0" ixy="0" ixz="0" iyy="0" iyz="0" izz="0" />-->
        </inertial>
        <visual>
            <origin rpy="0 0 0" xyz="0 0 0" />
            <geometry>
                <mesh filename="package://tracer_description/meshes/tracer_wheel.dae" />
                <!--<cylinder length="0.0787019" radius="0.0457774"/>-->
            </geometry>
        </visual>
        <collision>
            <origin rpy="0 0 0" xyz="0 0 0" />
            <geometry>
                <mesh filename="package://tracer_description/meshes/tracer_wheel.dae" />
                <!--<cylinder length="0.0787019" radius="0.0457774"/>-->
            </geometry>
        </collision>
    </link>
    <joint name="right_wheel" type="continuous">
        <!--<origin
                  xyz="0.14547 0.20835 -0.07424"
                  rpy="0 1.57 0" />-->
        <parent link="base_link" />
        <child link="right_wheel_link" />
        <origin rpy="0 0 0" xyz="0 -0.17 -0.082" />
        <axis rpy="0 0 0" xyz="0 1 0" />
    </joint>
    <link name="left_wheel_link">
        <!--<inertial>
            <mass value="3" />
                <origin
                        xyz="0.162297526351148 0.159063056237198 -0.160000047342231"
                        rpy="0 0 0" />
                        <inertia ixx="0.7171" ixy="0" ixz="0" iyy="0.1361" iyz="0" izz="0.7171" />
            </inertial>
            <visual>
                <origin xyz="0 0 0" rpy="0 0 0" />
                <geometry>
                    <mesh filename="package://tracer_description/meshes/wheel.dae" />
                </geometry>
            </visual>-->
        <inertial>
            <mass value="6" />
            <origin xyz="0 0 0" rpy="0 0 0" />
            <inertia ixx="0.7171" ixy="0" ixz="0" iyy="0.1361" iyz="0" izz="0.7171" />
            <!--<inertia ixx="0" ixy="0" ixz="0" iyy="0" iyz="0" izz="0" />-->
        </inertial>
        <visual>
            <origin rpy="0 0 0" xyz="0 0 0" />
            <geometry>
                <mesh filename="package://tracer_description/meshes/tracer_wheel.dae" />
                <!--<cylinder length="0.0787019" radius="0.0457774"/>-->
            </geometry>
        </visual>
        <collision>
            <origin rpy="0 0 0" xyz="0 0 0" />
            <geometry>
                <mesh filename="package://tracer_description/meshes/tracer_wheel.dae" />
                <!--<cylinder length="0.0787019" radius="0.0457774"/>-->
            </geometry>
        </collision>
    </link>
    <joint name="left_wheel" type="continuous">
        <!--<origin
                  xyz="-0.17453 0.20835 -0.07424"
                  rpy="0 -1.57 0" />-->
        <parent link="base_link" />
        <child link="left_wheel_link" />
        <origin rpy="3.14 0 0" xyz="0 0.17 -0.082" />
        <axis rpy="0 0 0" xyz="0 1 0" />
    </joint>
    <!--tracer castor wheel-->
    <link name="fl_castor_link">
        <inertial>
            <mass value="1" />
            <origin xyz="0 0 0" />
            <inertia ixx="0.7171" ixy="0" ixz="0" iyy="0.1361" iyz="0" izz="0.7171" />
        </inertial>
        <visual>
            <geometry>
                <!--<cylinder length="${castor_length}" radius="${castor_radius}"/>-->
                <mesh filename="package://tracer_description/meshes/castor_joint.dae" />
            </geometry>
            <!--<material name="black">
                        <color rgba="255 255 255 1"/>
                   </material>-->
        </visual>
        <!--<collision>
              <origin
                xyz="0 0 0"
                rpy="0 0 0" />
              <geometry>
                <cylinder length="${castor_length}" radius="${castor_radius}"/>
                <mesh filename="package://tracer_description/meshes/castor_joint.dae" />
              </geometry>
            </collision>-->
    </link>
    <joint name="fl_castor_wheel" type="continuous">
        <origin rpy="-1.57 0 0" xyz="0.18955 0.17 -0.0380886" />
        <parent link="base_link" />
        <child link="fl_castor_link" />
        <axis rpy="0 0 0" xyz="0 1 0" />
    </joint>
    <link name="fr_castor_link">
        <inertial>
            <mass value="1" />
            <origin xyz="0 0 0" />
            <inertia ixx="0.7171" ixy="0" ixz="0" iyy="0.1361" iyz="0" izz="0.7171" />
        </inertial>
        <visual>
            <geometry>
                <!--<cylinder length="${castor_length}" radius="${castor_radius}"/>-->
                <mesh filename="package://tracer_description/meshes/castor_joint.dae" />
            </geometry>
            <!--<material name="black">
                        <color rgba="255 255 255 1"/>
                   </material>-->
        </visual>
        <!--<collision>
              <origin
                xyz="0 0 0"
                rpy="0 0 0" />
              <geometry>
                <cylinder length="${castor_length}" radius="${castor_radius}"/>
                <mesh filename="package://tracer_description/meshes/castor_joint.dae" />
              </geometry>
            </collision>-->
    </link>
    <joint name="fr_castor_wheel" type="continuous">
        <origin rpy="-1.57 0 0" xyz="0.18955 -0.17 -0.0380886" />
        <parent link="base_link" />
        <child link="fr_castor_link" />
        <axis rpy="0 0 0" xyz="0 1 0" />
    </joint>
    <link name="rr_castor_link">
        <inertial>
            <mass value="1" />
            <origin xyz="0 0 0" />
            <inertia ixx="0.7171" ixy="0" ixz="0" iyy="0.1361" iyz="0" izz="0.7171" />
        </inertial>
        <visual>
            <geometry>
                <!--<cylinder length="${castor_length}" radius="${castor_radius}"/>-->
                <mesh filename="package://tracer_description/meshes/castor_joint.dae" />
            </geometry>
            <!-- <material name="black">
                        <color rgba="255 255 255 1"/>
                   </material>-->
        </visual>
        <!--<collision>
              <origin
                xyz="0 0 0"
                rpy="0 0 0" />
              <geometry>
                <cylinder length="${castor_length}" radius="${castor_radius}"/>
                <mesh filename="package://tracer_description/meshes/castor_joint.dae" />
              </geometry>
            </collision>-->
    </link>
    <joint name="rr_castor_wheel" type="continuous">
        <origin rpy="-1.57 0 0" xyz="-0.18955 -0.17 -0.0380886" />
        <parent link="base_link" />
        <child link="rr_castor_link" />
        <axis rpy="0 0 0" xyz="0 1 0" />
    </joint>
    <link name="rl_castor_link">
        <inertial>
            <mass value="1" />
            <origin xyz="0 0 0" />
            <inertia ixx="0.7171" ixy="0" ixz="0" iyy="0.1361" iyz="0" izz="0.7171" />
        </inertial>
        <visual>
            <geometry>
                <!--<cylinder length="${castor_length}" radius="${castor_radius}"/>-->
                <mesh filename="package://tracer_description/meshes/castor_joint.dae" />
            </geometry>
            <!--<material name="black">
                        <color rgba="255 255 255 1"/>
                   </material>-->
        </visual>
        <!-- <collision>
              <origin
                xyz="0 0 0"
                rpy="0 0 0" />
              <geometry>
                <cylinder length="${castor_length}" radius="${castor_radius}"/>
                <mesh filename="package://tracer_description/meshes/castor_joint.dae" />
              </geometry>
            </collision>-->
    </link>
    <joint name="rl_castor_wheel" type="continuous">
        <origin rpy="-1.57 0 0" xyz="-0.18955 0.17 -0.0380886" />
        <parent link="base_link" />
        <child link="rl_castor_link" />
        <axis rpy="0 0 0" xyz="0 1 0" />
    </joint>
    <link name="fl_wheel_link">
        <inertial>
            <mass value="1" />
            <origin xyz="0 0 0" rpy="0 0 0" />
            <inertia ixx="0.3131" ixy="0" ixz="0" iyy="0.3131" iyz="0" izz="0.1361" />
            <!--<inertia ixx="0" ixy="0" ixz="0" iyy="0" iyz="0" izz="0" />-->
        </inertial>
        <visual>
            <geometry>
                <!--<cylinder length="0.04653" radius="0.036"/>-->
                <!--<sphere radius="0.0457774"/>-->
                <mesh filename="package://tracer_description/meshes/castor.dae" />
            </geometry>
            <!--<material name="black">
                    <color rgba="255 255 255 1"/>
               </material>-->
        </visual>
        <collision>
            <origin rpy="0 0 0" xyz="0 0 0" />
            <geometry>
                --&gt;
                <!--<cylinder length="0.04653" radius="0.036"/>-->
                <!--<cylinder length="0.0787019" radius="0.0457774"/>-->
                <!--<sphere radius="0.0457774"/>-->
                <mesh filename="package://tracer_description/meshes/castor.dae" />
            </geometry>
        </collision>
    </link>
    <joint name="fl_wheel" type="continuous">
        <!--<origin
                  xyz="0.14547 0.20835 -0.07424"
                  rpy="0 1.57 0" />-->
        <parent link="fl_castor_link" />
        <child link="fl_wheel_link" />
        <dynamics damping="0.0" friction="0.0" />
        <origin rpy="0 0 0" xyz="-0.0218084 0.067 0" />
        <axis rpy="0 0 0" xyz="0 0 1" />
    </joint>
    <link name="fr_wheel_link">
        <inertial>
            <mass value="1" />
            <origin xyz="0 0 0" rpy="0 0 0" />
            <inertia ixx="0.3131" ixy="0" ixz="0" iyy="0.3131" iyz="0" izz="0.1361" />
            <!--<inertia ixx="0" ixy="0" ixz="0" iyy="0" iyz="0" izz="0" />-->
        </inertial>
        <visual>
            <geometry>
                <!--<cylinder length="0.04653" radius="0.036"/>-->
                <!--<sphere radius="0.0457774"/>-->
                <mesh filename="package://tracer_description/meshes/castor.dae" />
            </geometry>
            <!--<material name="black">
                   <color rgba="255 255 255 1"/>
                   </material>-->
        </visual>
        <collision>
            <origin rpy="0 0 0" xyz="0 0 0" />
            <geometry>
                --&gt;
                <!--<cylinder length="0.04653" radius="0.036"/>-->
                <!--<cylinder length="0.0787019" radius="0.0457774"/>-->
                <!--<sphere radius="0.0457774"/>-->
                <mesh filename="package://tracer_description/meshes/castor.dae" />
            </geometry>
        </collision>
    </link>
    <joint name="fr_wheel" type="continuous">
        <!--<origin
                  xyz="0.14547 0.20835 -0.07424"
                  rpy="0 1.57 0" />-->
        <parent link="fr_castor_link" />
        <child link="fr_wheel_link" />
        <dynamics damping="0.0" friction="0.0" />
        <origin rpy="0 0 0" xyz="-0.0218084 0.067 0" />
        <axis rpy="0 0 0" xyz="0 0 1" />
    </joint>
    <link name="rr_wheel_link">
        <inertial>
            <mass value="1" />
            <origin xyz="0 0 0" rpy="0 0 0" />
            <inertia ixx="0.3131" ixy="0" ixz="0" iyy="0.3131" iyz="0" izz="0.1361" />
            <!--<inertia ixx="0" ixy="0" ixz="0" iyy="0" iyz="0" izz="0" />-->
        </inertial>
        <visual>
            <geometry>
                <!--<cylinder length="0.04653" radius="0.036"/>-->
                <!--<sphere radius="0.0457774"/>-->
                <mesh filename="package://tracer_description/meshes/castor.dae" />
            </geometry>
            <!--<material name="black">
                        <color rgba="255 255 255 1"/>
                   </material>-->
        </visual>
        <collision>
            <origin rpy="0 0 0" xyz="0 0 0" />
            <geometry>
                <!--<mesh filename="package://tracer_description/meshes/wheel.dae" />-->
                <!--<cylinder length="0.04653" radius="0.036"/>-->
                <!-- <sphere radius="0.0457774"/>-->
                <mesh filename="package://tracer_description/meshes/castor.dae" />
            </geometry>
        </collision>
    </link>
    <joint name="rr_wheel" type="continuous">
        <!--<origin
                  xyz="0.14547 0.20835 -0.07424"
                  rpy="0 1.57 0" />-->
        <parent link="rr_castor_link" />
        <child link="rr_wheel_link" />
        <dynamics damping="0.0" friction="0.0" />
        <origin rpy="0 0 0" xyz="-0.0218084 0.067 0" />
        <axis rpy="0 0 0" xyz="0 0 1" />
    </joint>
    <link name="rl_wheel_link">
        <inertial>
            <mass value="1" />
            <origin xyz="0 0 0" rpy="0 0 0" />
            <inertia ixx="0.3131" ixy="0" ixz="0" iyy="0.3131" iyz="0" izz="0.1361" />
            <!--<inertia ixx="0" ixy="0" ixz="0" iyy="0" iyz="0" izz="0" />-->
        </inertial>
        <visual>
            <geometry>
                <!--<cylinder length="0.04653" radius="0.036"/>-->
                <!--<sphere radius="0.0457774"/>-->
                <mesh filename="package://tracer_description/meshes/castor.dae" />
            </geometry>
            <!--<material name="black">
                        <color rgba="255 255 255 1"/>
                   </material>-->
        </visual>
        <collision>
            <origin rpy="0 0 0" xyz="0 0 0" />
            <geometry>
                <!--<cylinder length="0.04653" radius="0.036"/>-->
                <!--<cylinder length="0.0787019" radius="0.0457774"/>-->
                <!--<sphere radius="0.0457774"/>-->
                <mesh filename="package://tracer_description/meshes/castor.dae" />
            </geometry>
        </collision>
    </link>
    <joint name="rl_wheel" type="continuous">
        <!--<origin
                  xyz="0.14547 0.20835 -0.07424"
                  rpy="0 1.57 0" />-->
        <parent link="rl_castor_link" />
        <child link="rl_wheel_link" />
        <dynamics damping="0.0" friction="0.0" />
        <origin rpy="0 0 0" xyz="-0.0218084 0.067 0" />
        <axis rpy="0 0 0" xyz="0 0 1" />
    </joint>
    <!-- This file is a placeholder which is included by default from
       husky.urdf.xacro. If a robot is being customized and requires
       additional URDF, set the HUSKY_URDF_EXTRAS environment variable
       to the full path of the file you would like included. -->
    <!-- Additional definitions for simulation -->
    <!-- <gazebo reference="base_link">
        <material>Gazebo/Grey</material>
    </gazebo> -->
    <transmission name="right_wheel_trans" type="SimpleTransmission">
        <type>transmission_interface/SimpleTransmission</type>
        <actuator name="right_wheel_motor">
            <mechanicalReduction>1</mechanicalReduction>
            <hardwareInterface>hardware_interface/EffortJointInterface</hardwareInterface>
        </actuator>
        <joint name="right_wheel">
            <hardwareInterface>hardware_interface/VelocityJointInterface</hardwareInterface>
        </joint>
    </transmission>
    <transmission name="left_wheel_trans" type="SimpleTransmission">
        <type>transmission_interface/SimpleTransmission</type>
        <actuator name="left_wheel_motor">
            <mechanicalReduction>1</mechanicalReduction>
            <hardwareInterface>hardware_interface/EffortJointInterface</hardwareInterface>
        </actuator>
        <joint name="left_wheel">
            <hardwareInterface>hardware_interface/VelocityJointInterface</hardwareInterface>
        </joint>
    </transmission>
    <transmission name="fl_wheel_trans" type="SimpleTransmission">
        <type>transmission_interface/SimpleTransmission</type>
        <actuator name="fl_wheel_motor">
            <mechanicalReduction>1</mechanicalReduction>
            <hardwareInterface>hardware_interface/EffortJointInterface</hardwareInterface>
        </actuator>
        <joint name="fl_wheel">
            <hardwareInterface>hardware_interface/VelocityJointInterface</hardwareInterface>
        </joint>
    </transmission>
    <transmission name="fr_wheel_trans" type="SimpleTransmission">
        <type>transmission_interface/SimpleTransmission</type>
        <actuator name="fr_wheel_motor">
            <mechanicalReduction>1</mechanicalReduction>
            <hardwareInterface>hardware_interface/EffortJointInterface</hardwareInterface>
        </actuator>
        <joint name="fr_wheel">
            <hardwareInterface>hardware_interface/VelocityJointInterface</hardwareInterface>
        </joint>
    </transmission>
    <transmission name="rr_wheel_trans" type="SimpleTransmission">
        <type>transmission_interface/SimpleTransmission</type>
        <actuator name="rr_wheel_motor">
            <mechanicalReduction>1</mechanicalReduction>
            <hardwareInterface>hardware_interface/EffortJointInterface</hardwareInterface>
        </actuator>
        <joint name="rr_wheel">
            <hardwareInterface>hardware_interface/VelocityJointInterface</hardwareInterface>
        </joint>
    </transmission>
    <transmission name="rl_wheel_trans" type="SimpleTransmission">
        <type>transmission_interface/SimpleTransmission</type>
        <actuator name="rl_wheel_motor">
            <mechanicalReduction>1</mechanicalReduction>
            <hardwareInterface>hardware_interface/EffortJointInterface</hardwareInterface>
        </actuator>
        <joint name="rl_wheel">
            <hardwareInterface>hardware_interface/VelocityJointInterface</hardwareInterface>
        </joint>
    </transmission>
    <transmission name="fl_castor_wheel_trans" type="SimpleTransmission">
        <type>transmission_interface/SimpleTransmission</type>
        <actuator name="fl_castor_wheel_motor">
            <mechanicalReduction>1</mechanicalReduction>
            <hardwareInterface>hardware_interface/EffortJointInterface</hardwareInterface>
        </actuator>
        <joint name="fl_castor_wheel">
            <hardwareInterface>hardware_interface/VelocityJointInterface</hardwareInterface>
        </joint>
    </transmission>
    <transmission name="fr_castor_wheel_trans" type="SimpleTransmission">
        <type>transmission_interface/SimpleTransmission</type>
        <actuator name="fr_castor_wheel_motor">
            <mechanicalReduction>1</mechanicalReduction>
            <hardwareInterface>hardware_interface/EffortJointInterface</hardwareInterface>
        </actuator>
        <joint name="fr_castor_wheel">
            <hardwareInterface>hardware_interface/VelocityJointInterface</hardwareInterface>
        </joint>
    </transmission>
    <transmission name="rr_castor_wheel_trans" type="SimpleTransmission">
        <type>transmission_interface/SimpleTransmission</type>
        <actuator name="rr_castor_wheel_motor">
            <mechanicalReduction>1</mechanicalReduction>
            <hardwareInterface>hardware_interface/EffortJointInterface</hardwareInterface>
        </actuator>
        <joint name="rr_castor_wheel">
            <hardwareInterface>hardware_interface/VelocityJointInterface</hardwareInterface>
        </joint>
    </transmission>
    <transmission name="rl_castor_wheel_trans" type="SimpleTransmission">
        <type>transmission_interface/SimpleTransmission</type>
        <actuator name="rl_castor_wheel_motor">
            <mechanicalReduction>1</mechanicalReduction>
            <hardwareInterface>hardware_interface/EffortJointInterface</hardwareInterface>
        </actuator>
        <joint name="rl_castor_wheel">
            <hardwareInterface>hardware_interface/VelocityJointInterface</hardwareInterface>
        </joint>
    </transmission>
    <!-- Controller configurations -->
    <gazebo>
        <plugin filename="libgazebo_ros_control.so" name="gazebo_ros_control">
            <robotNamespace>/</robotNamespace>
        </plugin>
    </gazebo>
    <!-- kp spring constant, kd damping constant -->
    <gazebo>
        <mu1 value="1.0" />
        <mu2 value="0.9" />
        <kp value="10000000.0" />
        <kd value="1.0" />
        <fdir1 value="1 0 0" />
        <minDepth value="0.001" />
        <maxContacts value="64" />
    </gazebo>
    <!-- <gazebo>
        <plugin name="skid_steer_drive_controller" filename="libgazebo_ros_skid_steer_drive.so">
            <updateRate>100.0</updateRate>
            <robotNamespace></robotNamespace>
            <leftFrontJoint>left_wheel</leftFrontJoint>
            <rightFrontJoint>right_wheel</rightFrontJoint>
            <wheelSeparation>2</wheelSeparation>
            <wheelDiameter>0.32918</wheelDiameter>
            <robotBaseFrame>base_link</robotBaseFrame>
            <torque>1000</torque>
            <commandTopic>cmd_vel</commandTopic>
            <broadcastTF>true</broadcastTF>
            <publishOdomTF>true</publishOdomTF>
            <odometryTopic>odom</odometryTopic>
            <odometryFrame>odom</odometryFrame>
            <covariance_x>0.000100</covariance_x>
            <covariance_y>0.000100</covariance_y>
            <covariance_yaw>0.010000</covariance_yaw>
        </plugin>
    </gazebo> -->
    <!-- <gazebo>
        <plugin name="object_controller" filename="libgazebo_ros_planar_move.so">
            <commandTopic>cmd_vel</commandTopic>
            <odometryTopic>odom</odometryTopic>
            <odometryFrame>odom</odometryFrame>
            <odometryRate>20.0</odometryRate>
            <robotBaseFrame>base_footprint</robotBaseFrame>
        </plugin>
    </gazebo> -->
    <!-- 控制器 -->
    <gazebo>
        <!-- 差速控制器 -->
        <plugin filename="libgazebo_ros_diff_drive.so" name="differential_drive_controller">
            <rosDebugLevel>Debug</rosDebugLevel>
            <!-- <publishWheelTF>true</publishWheelTF> -->
            <robotNamespace>/</robotNamespace>
            <publishTf>1</publishTf>
            <!-- <publishWheelJointState>true</publishWheelJointState> -->
            <alwaysOn>true</alwaysOn>
            <updateRate>30</updateRate>
            <legacyMode>true</legacyMode>
            <leftJoint>left_wheel</leftJoint>
            <!-- 左轮 -->
            <rightJoint>right_wheel</rightJoint>
            <!-- 右轮 -->
            <wheelSeparation>2</wheelSeparation>
            <!-- 车轮间距 -->
            <wheelDiameter>0.32918</wheelDiameter>
            <!-- 车轮直径 -->
            <broadcastTF>1</broadcastTF>
            <publishWheelTF>false</publishWheelTF>
            <publishWheelJointState>false</publishWheelJointState>
            <wheelTorque>30</wheelTorque>
            <wheelAcceleration>1.8</wheelAcceleration>
            <commandTopic>cmd_vel</commandTopic>
            <!-- 运动控制话题 -->
            <odometryFrame>odom</odometryFrame>
            <odometryTopic>odom</odometryTopic>
            <!-- 里程计话题 -->
            <robotBaseFrame>base_link</robotBaseFrame>
            <!-- 根坐标系 -->
        </plugin>
    </gazebo>
    <link name="aluminium_base_link">
        <inertial>
            <origin rpy="0 0 0" xyz="6.93889390390723E-18 -3.46944695195361E-18 0.1" />
            <mass value="0.252739239169835" />
            <inertia ixx="0.000880444836748547" ixy="-1.17427335239852E-20" ixz="-1.0362530110532E-21" iyy="0.000884007661098085" iyz="2.02761635868414E-20" izz="7.95242367143988E-05" />
        </inertial>
        <visual>
            <origin rpy="0 0 0" xyz="0 0 0" />
            <geometry>
                <mesh filename="package://aluminium/meshes/aluminium_base_link.STL" />
            </geometry>
            <material name="">
                <color rgba="0.898039215686275 0.917647058823529 0.929411764705882 1" />
            </material>
        </visual>
        <collision>
            <origin rpy="0 0 0" xyz="0 0 0" />
            <geometry>
                <mesh filename="package://aluminium/meshes/aluminium_base_link.STL" />
            </geometry>
        </collision>
    </link>
    <link name="aluminium_2_base_link">
        <inertial>
            <origin rpy="0 0 0" xyz="6.93889390390723E-18 -3.46944695195361E-18 0.1" />
            <mass value="0.252739239169835" />
            <inertia ixx="0.000880444836748547" ixy="-1.17427335239852E-20" ixz="-1.0362530110532E-21" iyy="0.000884007661098085" iyz="2.02761635868414E-20" izz="7.95242367143988E-05" />
        </inertial>
        <visual>
            <origin rpy="0 0 0" xyz="0 0 0" />
            <geometry>
                <mesh filename="package://aluminium/meshes/aluminium_base_link.STL" />
            </geometry>
            <material name="">
                <color rgba="0.898039215686275 0.917647058823529 0.929411764705882 1" />
            </material>
        </visual>
        <collision>
            <origin rpy="0 0 0" xyz="0 0 0" />
            <geometry>
                <mesh filename="package://aluminium/meshes/aluminium_base_link.STL" />
            </geometry>
        </collision>
    </link>
    <link name="aluminium_3_base_link">
        <inertial>
            <origin rpy="0 0 0" xyz="6.93889390390723E-18 -3.46944695195361E-18 0.1" />
            <mass value="0.252739239169835" />
            <inertia ixx="0.000880444836748547" ixy="-1.17427335239852E-20" ixz="-1.0362530110532E-21" iyy="0.000884007661098085" iyz="2.02761635868414E-20" izz="7.95242367143988E-05" />
        </inertial>
        <visual>
            <origin rpy="0 0 0" xyz="0 0 0" />
            <geometry>
                <mesh filename="package://aluminium/meshes/aluminium_base_link.STL" />
            </geometry>
            <material name="">
                <color rgba="0.898039215686275 0.917647058823529 0.929411764705882 1" />
            </material>
        </visual>
        <collision>
            <origin rpy="0 0 0" xyz="0 0 0" />
            <geometry>
                <mesh filename="package://aluminium/meshes/aluminium_base_link.STL" />
            </geometry>
        </collision>
    </link>
    <link name="aluminium_4_base_link">
        <inertial>
            <origin rpy="0 0 0" xyz="6.93889390390723E-18 -3.46944695195361E-18 0.1" />
            <mass value="0.252739239169835" />
            <inertia ixx="0.000880444836748547" ixy="-1.17427335239852E-20" ixz="-1.0362530110532E-21" iyy="0.000884007661098085" iyz="2.02761635868414E-20" izz="7.95242367143988E-05" />
        </inertial>
        <visual>
            <origin rpy="0 0 0" xyz="0 0 0" />
            <geometry>
                <mesh filename="package://aluminium/meshes/aluminium_base_link.STL" />
            </geometry>
            <material name="">
                <color rgba="0.898039215686275 0.917647058823529 0.929411764705882 1" />
            </material>
        </visual>
        <collision>
            <origin rpy="0 0 0" xyz="0 0 0" />
            <geometry>
                <mesh filename="package://aluminium/meshes/aluminium_base_link.STL" />
            </geometry>
        </collision>
    </link>
    <link name="urbase_base_link">
        <inertial>
            <origin rpy="0 0 0" xyz="-0.0821499280748119 -2.5975459884737E-05 -0.00250008544254768" />
            <mass value="0.965960559010444" />
            <inertia ixx="0.0122165277186615" ixy="-4.00804681294595E-06" ixz="-1.87749280324881E-10" iyy="0.0276040033352521" iyz="4.28906904561782E-10" izz="0.0398165064505868" />
        </inertial>
        <visual>
            <origin rpy="0 0 0" xyz="0 0 0" />
            <geometry>
                <mesh filename="package://second_base/meshes/urbase_base_link.STL" />
            </geometry>
            <material name="">
                <color rgba="1 1 1 1" />
            </material>
        </visual>
        <collision>
            <origin rpy="0 0 0" xyz="0 0 0" />
            <geometry>
                <mesh filename="package://second_base/meshes/urbase_base_link.STL" />
            </geometry>
        </collision>
    </link>
    <!-- LINK -->
    <link name="jaka_base_link" />
    <link name="Link_6_45" />
    <link name="camera_link" />
    <link name="Link_0">
        <inertial>
            <origin rpy="0 0 0" xyz="0.00096371 8.8222E-08 0.019555" />
            <mass value="4.0392" />
            <inertia ixx="0.0048763" ixy="-1.8056E-07" ixz="2.5196E-05" iyy="0.0068003" iyz="-1.7678E-09" izz="0.010618" />
        </inertial>
        <visual>
            <origin rpy="0 0 0" xyz="0 0 0" />
            <geometry>
                <mesh filename="package://jaka_description/meshes/jaka_zu5_meshes/Link_0.STL" />
            </geometry>
            <material name="">
                <color rgba="0.84 0 0.25 1" />
            </material>
        </visual>
        <collision>
            <origin rpy="0 0 0" xyz="0 0 0" />
            <geometry>
                <mesh filename="package://jaka_description/meshes/jaka_zu5_meshes/Link_0.STL" />
            </geometry>
        </collision>
    </link>
    <link name="Link_1">
        <inertial>
            <origin rpy="0 0 0" xyz="-2.5186E-07 0.0033226 -0.001509" />
            <mass value="15.135" />
            <inertia ixx="0.044302" ixy="1.5349E-07" ixz="-6.1966E-07" iyy="0.043091" iyz="1.4326E-05" izz="0.030523" />
        </inertial>
        <visual>
            <origin rpy="0 0 0" xyz="0 0 0" />
            <geometry>
                <mesh filename="package://jaka_description/meshes/jaka_zu5_meshes/Link_1.STL" />
            </geometry>
            <material name="">
                <color rgba="0.84 0 0.25 1" />
            </material>
        </visual>
        <collision>
            <origin rpy="0 0 0" xyz="0 0 0" />
            <geometry>
                <mesh filename="package://jaka_description/meshes/jaka_zu5_meshes/Link_1.STL" />
            </geometry>
        </collision>
    </link>
    <link name="Link_2">
        <inertial>
            <origin rpy="0 0 0" xyz="0.215 6.4325E-09 -0.14315" />
            <mass value="45.847" />
            <inertia ixx="0.10377" ixy="-1.3562E-06" ixz="2.544E-07" iyy="1.5964" iyz="2.1509E-08" izz="1.5689" />
        </inertial>
        <visual>
            <origin rpy="0 0 0" xyz="0 0 0" />
            <geometry>
                <mesh filename="package://jaka_description/meshes/jaka_zu5_meshes/Link_2.STL" />
            </geometry>
            <material name="">
                <color rgba="0.84 0 0.25 1" />
            </material>
        </visual>
        <collision>
            <origin rpy="0 0 0" xyz="0 0 0" />
            <geometry>
                <mesh filename="package://jaka_description/meshes/jaka_zu5_meshes/Link_2.STL" />
            </geometry>
        </collision>
    </link>
    <link name="Link_3">
        <inertial>
            <origin rpy="0 0 0" xyz="0.19087 -1.1862E-05 -0.010587" />
            <mass value="18.069" />
            <inertia ixx="0.022066" ixy="-3.4554E-06" ixz="-0.022609" iyy="0.41632" iyz="1.1508E-08" izz="0.41071" />
        </inertial>
        <visual>
            <origin rpy="0 0 0" xyz="0 0 0" />
            <geometry>
                <mesh filename="package://jaka_description/meshes/jaka_zu5_meshes/Link_3.STL" />
            </geometry>
            <material name="">
                <color rgba="0.84 0 0.25 1" />
            </material>
        </visual>
        <collision>
            <origin rpy="0 0 0" xyz="0 0 0" />
            <geometry>
                <mesh filename="package://jaka_description/meshes/jaka_zu5_meshes/Link_3.STL" />
            </geometry>
        </collision>
    </link>
    <link name="Link_4">
        <inertial>
            <origin rpy="0 0 0" xyz="-2.1345E-06 -0.0058004 0.0026717" />
            <mass value="5.5525" />
            <inertia ixx="0.0092564" ixy="1.1341E-07" ixz="-1.2578E-08" iyy="0.0052251" iyz="-8.3499E-05" izz="0.0089683" />
        </inertial>
        <visual>
            <origin rpy="0 0 0" xyz="0 0 0" />
            <geometry>
                <mesh filename="package://jaka_description/meshes/jaka_zu5_meshes/Link_4.STL" />
            </geometry>
            <material name="">
                <color rgba="0.84 0 0.25 1" />
            </material>
        </visual>
        <collision>
            <origin rpy="0 0 0" xyz="0 0 0" />
            <geometry>
                <mesh filename="package://jaka_description/meshes/jaka_zu5_meshes/Link_4.STL" />
            </geometry>
        </collision>
    </link>
    <link name="Link_5">
        <inertial>
            <origin rpy="0 0 0" xyz="-2.0304E-06 -0.0028889 -0.0023424" />
            <mass value="6.3339" />
            <inertia ixx="0.012993" ixy="-1.0764E-07" ixz="5.8559E-09" iyy="0.0058454" iyz="4.5426E-05" izz="0.0127" />
        </inertial>
        <visual>
            <origin rpy="0 0 0" xyz="0 0 0" />
            <geometry>
                <mesh filename="package://jaka_description/meshes/jaka_zu5_meshes/Link_5.STL" />
            </geometry>
            <material name="">
                <color rgba="0.84 0 0.25 1" />
            </material>
        </visual>
        <collision>
            <origin rpy="0 0 0" xyz="0 0 0" />
            <geometry>
                <mesh filename="package://jaka_description/meshes/jaka_zu5_meshes/Link_5.STL" />
            </geometry>
        </collision>
    </link>
    <link name="Link_6">
        <inertial>
            <origin rpy="0 0 0" xyz="2.7652E-05 -1.3485E-05 -0.021245" />
            <mass value="1.4169" />
            <inertia ixx="0.00071853" ixy="-6.9778E-07" ixz="-6.378E-07" iyy="0.00072375" iyz="8.3072E-07" izz="0.0011337" />
        </inertial>
        <visual>
            <origin rpy="0 0 0" xyz="0 0 0" />
            <geometry>
                <mesh filename="package://jaka_description/meshes/jaka_zu5_meshes/Link_6.STL" />
            </geometry>
            <material name="">
                <color rgba="0.84 0 0.25 1" />
            </material>
        </visual>
        <collision>
            <origin rpy="0 0 0" xyz="0 0 0" />
            <geometry>
                <mesh filename="package://jaka_description/meshes/jaka_zu5_meshes/Link_6.STL" />
            </geometry>
        </collision>
    </link>
    <!-- JOINT -->
    <joint name="fixed" type="fixed">
        <origin rpy="0 0 -1.57" xyz="0 0 0" />
        <parent link="jaka_base_link" />
        <child link="Link_0" />
    </joint>
    <joint name="fixed_2" type="fixed">
        <origin rpy="0.7854 -1.5708 0" xyz="0 0 0" />
        <parent link="Link_6" />
        <child link="Link_6_45" />
    </joint>
    <joint name="fixed_3" type="fixed">
        <origin rpy="0 0 0" xyz="0.09 0 0.06" />
        <parent link="Link_6_45" />
        <child link="camera_link" />
    </joint>
    <joint name="joint_1" type="revolute">
        <origin rpy="0 0 0" xyz="0 0 0.12015" />
        <parent link="Link_0" />
        <child link="Link_1" />
        <axis xyz="0 0 1" />
        <limit effort="2000" lower="-6.28" upper="6.28" velocity="3.14" />
    </joint>
    <joint name="joint_2" type="revolute">
        <origin rpy="1.5708 0 0" xyz="0 0 0" />
        <parent link="Link_1" />
        <child link="Link_2" />
        <axis xyz="0 0 1" />
        <limit effort="5000" lower="-1.48" upper="4.62" velocity="3.14" />
    </joint>
    <joint name="joint_3" type="revolute">
        <origin rpy="0 0 0" xyz="0.43 0 0" />
        <parent link="Link_2" />
        <child link="Link_3" />
        <axis xyz="0 0 1" />
        <limit effort="5000" lower="-3.05" upper="3.05" velocity="3.14" />
    </joint>
    <joint name="joint_4" type="revolute">
        <origin rpy="0 0 0" xyz="0.3685 -1.185E-05 -0.114" />
        <parent link="Link_3" />
        <child link="Link_4" />
        <axis xyz="0 0 1" />
        <limit effort="2000" lower="-1.48" upper="4.62" velocity="3.14" />
    </joint>
    <joint name="joint_5" type="revolute">
        <origin rpy="1.5708 0 0" xyz="0 -0.1135 0" />
        <parent link="Link_4" />
        <child link="Link_5" />
        <axis xyz="0 0 1" />
        <limit effort="3000" lower="-6.28" upper="6.28" velocity="3.14" />
    </joint>
    <joint name="joint_6" type="revolute">
        <origin rpy="-1.5708 0 0" xyz="0 0.107 0" />
        <parent link="Link_5" />
        <child link="Link_6" />
        <axis xyz="0 0 1" />
        <limit effort="1000" lower="-6.28" upper="6.28" velocity="3.14" />
    </joint>
    <transmission name="trans_joint_1">
        <type>transmission_interface/SimpleTransmission</type>
        <joint name="joint_1">
            <hardwareInterface>hardware_interface/PositionJointInterface</hardwareInterface>
        </joint>
        <actuator name="joint_1_motor">
            <hardwareInterface>hardware_interface/PositionJointInterface</hardwareInterface>
            <mechanicalReduction>1</mechanicalReduction>
        </actuator>
    </transmission>
    <transmission name="trans_joint_2">
        <type>transmission_interface/SimpleTransmission</type>
        <joint name="joint_2">
            <hardwareInterface>hardware_interface/PositionJointInterface</hardwareInterface>
        </joint>
        <actuator name="joint_2_motor">
            <hardwareInterface>hardware_interface/PositionJointInterface</hardwareInterface>
            <mechanicalReduction>1</mechanicalReduction>
        </actuator>
    </transmission>
    <transmission name="trans_joint_3">
        <type>transmission_interface/SimpleTransmission</type>
        <joint name="joint_3">
            <hardwareInterface>hardware_interface/PositionJointInterface</hardwareInterface>
        </joint>
        <actuator name="joint_3_motor">
            <hardwareInterface>hardware_interface/PositionJointInterface</hardwareInterface>
            <mechanicalReduction>1</mechanicalReduction>
        </actuator>
    </transmission>
    <transmission name="trans_joint_4">
        <type>transmission_interface/SimpleTransmission</type>
        <joint name="joint_4">
            <hardwareInterface>hardware_interface/PositionJointInterface</hardwareInterface>
        </joint>
        <actuator name="joint_4_motor">
            <hardwareInterface>hardware_interface/PositionJointInterface</hardwareInterface>
            <mechanicalReduction>1</mechanicalReduction>
        </actuator>
    </transmission>
    <transmission name="trans_joint_5">
        <type>transmission_interface/SimpleTransmission</type>
        <joint name="joint_5">
            <hardwareInterface>hardware_interface/PositionJointInterface</hardwareInterface>
        </joint>
        <actuator name="joint_5_motor">
            <hardwareInterface>hardware_interface/PositionJointInterface</hardwareInterface>
            <mechanicalReduction>1</mechanicalReduction>
        </actuator>
    </transmission>
    <transmission name="trans_joint_6">
        <type>transmission_interface/SimpleTransmission</type>
        <joint name="joint_6">
            <hardwareInterface>hardware_interface/PositionJointInterface</hardwareInterface>
        </joint>
        <actuator name="joint_6_motor">
            <hardwareInterface>hardware_interface/PositionJointInterface</hardwareInterface>
            <mechanicalReduction>1</mechanicalReduction>
        </actuator>
    </transmission>
    <gazebo>
        <plugin filename="libgazebo_ros_control.so" name="gazebo_ros_control">
            <robotNamespace>/</robotNamespace>
        </plugin>
    </gazebo>
    <material name="aluminum">
        <color rgba="0.5 0.5 0.5 1" />
    </material>
    <material name="plastic">
        <color rgba="0.1 0.1 0.1 1" />
    </material>
    <link name="robotiq_coupler">
        <visual>
            <geometry>
                <mesh filename="package://robotiq_description/meshes/robotiq_85_coupler.stl" />
            </geometry>
            <!--material
      name="flat_black"/-->
        </visual>
        <collision>
            <geometry>
                <mesh filename="package://robotiq_description/meshes/robotiq_85_coupler.stl" />
            </geometry>
        </collision>
        <inertial>
            <origin rpy="0 0 0" xyz="2.073e-05   1.45286e-03  -1.1049e-03" />
            <mass value="0.168" />
            <inertia ixx="6.69695624e-05" ixy="5.21511788e-09" ixz="-2.74383009e-08" iyy="7.85088161e-05" iyz="5.41105193e-07" izz="1.41819717e-04" />
        </inertial>
    </link>
    <!-- JOINT -->
    <joint name="tracer_aluminium" type="fixed">
        <origin rpy="0 0 0" xyz="-0.142 0.115 0.016 " />
        <parent link="base_link" />
        <child link="aluminium_base_link" />
    </joint>
    <joint name="tracer_aluminium_2" type="fixed">
        <origin rpy="0 0 0" xyz="-0.142 -0.115 0.016 " />
        <parent link="base_link" />
        <child link="aluminium_2_base_link" />
    </joint>
    <joint name="tracer_aluminium_3" type="fixed">
        <origin rpy="0 0 0" xyz="0.145 0.115 0.016 " />
        <parent link="base_link" />
        <child link="aluminium_3_base_link" />
    </joint>
    <joint name="tracer_aluminium_4" type="fixed">
        <origin rpy="0 0 0" xyz="0.145 -0.115 0.016 " />
        <parent link="base_link" />
        <child link="aluminium_4_base_link" />
    </joint>
    <joint name="tracer_base" type="fixed">
        <origin rpy="0 0 0" xyz="0.03 0 0.218 " />
        <parent link="base_link" />
        <child link="urbase_base_link" />
    </joint>
    <joint name="base_to_jaka" type="fixed">
        <parent link="base_link" />
        <child link="jaka_base_link" />
        <origin rpy="0 0 0" xyz="0 0 0.218" />
    </joint>
    <joint name="robotiq_coupler_joint" type="fixed">
        <origin rpy="0 0 -0.7853981634" xyz="0 0 0 " />
        <parent link="Link_6" />
        <child link="robotiq_coupler" />
    </joint>
    <joint name="robotiq_85_base_joint" type="fixed">
        <parent link="robotiq_coupler" />
        <child link="robotiq_85_base_link" />
        <origin rpy="0 -1.57 1.57" xyz="0 0 0.005" />
        <!--origin xyz="0 0 0" rpy="0 0 0"/-->
    </joint>
    <link name="robotiq_85_base_link">
        <visual>
            <geometry>
                <mesh filename="package://robotiq_description/meshes/visual/robotiq_85_base_link.dae" />
            </geometry>
        </visual>
        <collision>
            <geometry>
                <mesh filename="package://robotiq_description/meshes/collision/robotiq_85_base_link.stl" />
            </geometry>
        </collision>
        <inertial>
            <mass value="0.636951" />
            <origin xyz="0.0 0.0 0.0" rpy="0 0 0" />
            <inertia ixx="0.000380" ixy="0.000000" ixz="0.000000" iyx="0.000000" iyy="0.001110" iyz="0.000000" izx="0.000000" izy="0.000000" izz="0.001171" />
        </inertial>
    </link>
    <joint name="robotiq_85_left_knuckle_joint" type="fixed">
        <parent link="robotiq_85_base_link" />
        <child link="robotiq_85_left_knuckle_link" />
        <axis xyz="0 0 1" />
        <origin rpy="3.141592653589793 0.0 0.0" xyz="0.05490451627 0.03060114443 0.0" />
        <limit effort="1000" lower="0.0" upper="0.80285" velocity="0.5" />
    </joint>
    <joint name="robotiq_85_right_knuckle_joint" type="fixed">
        <parent link="robotiq_85_base_link" />
        <child link="robotiq_85_right_knuckle_link" />
        <axis xyz="0 0 1" />
        <origin rpy="0.0 0.0 0.0" xyz="0.05490451627 -0.03060114443 0.0" />
        <limit effort="1000" lower="-3.14" upper="3.14" velocity="100.0" />
        <!-- <mimic joint="${prefix}robotiq_85_left_knuckle_joint"/> -->
    </joint>
    <link name="robotiq_85_left_knuckle_link">
        <visual>
            <geometry>
                <mesh filename="package://robotiq_description/meshes/visual/robotiq_85_knuckle_link.dae" />
            </geometry>
        </visual>
        <collision>
            <geometry>
                <mesh filename="package://robotiq_description/meshes/collision/robotiq_85_knuckle_link.stl" />
            </geometry>
        </collision>
        <inertial>
            <mass value="0.018491" />
            <origin xyz="0.0 0.0 0.0" rpy="0 0 0" />
            <inertia ixx="0.000009" ixy="-0.000001" ixz="0.000000" iyx="-0.000001" iyy="0.000001" iyz="0.000000" izx="0.000000" izy="0.000000" izz="0.000010" />
        </inertial>
    </link>
    <link name="robotiq_85_right_knuckle_link">
        <visual>
            <geometry>
                <mesh filename="package://robotiq_description/meshes/visual/robotiq_85_knuckle_link.dae" />
            </geometry>
        </visual>
        <collision>
            <geometry>
                <mesh filename="package://robotiq_description/meshes/collision/robotiq_85_knuckle_link.stl" />
            </geometry>
        </collision>
        <inertial>
            <mass value="0.018491" />
            <origin xyz="0.0 0.0 0.0" rpy="0 0 0" />
            <inertia ixx="0.000009" ixy="-0.000001" ixz="0.000000" iyx="-0.000001" iyy="0.000001" iyz="0.000000" izx="0.000000" izy="0.000000" izz="0.000010" />
        </inertial>
    </link>
    <joint name="robotiq_85_left_finger_joint" type="fixed">
        <parent link="robotiq_85_left_knuckle_link" />
        <child link="robotiq_85_left_finger_link" />
        <origin rpy="0 0 0" xyz="-0.00408552455 -0.03148604435 0.0" />
    </joint>
    <joint name="robotiq_85_right_finger_joint" type="fixed">
        <parent link="robotiq_85_right_knuckle_link" />
        <child link="robotiq_85_right_finger_link" />
        <origin rpy="0 0 0" xyz="-0.00408552455 -0.03148604435 0.0" />
    </joint>
    <link name="robotiq_85_left_finger_link">
        <visual>
            <geometry>
                <mesh filename="package://robotiq_description/meshes/visual/robotiq_85_finger_link.dae" />
            </geometry>
        </visual>
        <collision>
            <geometry>
                <mesh filename="package://robotiq_description/meshes/collision/robotiq_85_finger_link.stl" />
            </geometry>
        </collision>
        <inertial>
            <mass value="0.027309" />
            <origin xyz="0.0 0.0 0.0" rpy="0 0 0" />
            <inertia ixx="0.000003" ixy="-0.000002" ixz="0.000000" iyx="-0.000002" iyy="0.000021" iyz="0.000000" izx="0.000000" izy="0.000000" izz="0.000020" />
        </inertial>
    </link>
    <link name="robotiq_85_right_finger_link">
        <visual>
            <geometry>
                <mesh filename="package://robotiq_description/meshes/visual/robotiq_85_finger_link.dae" />
            </geometry>
        </visual>
        <collision>
            <geometry>
                <mesh filename="package://robotiq_description/meshes/collision/robotiq_85_finger_link.stl" />
            </geometry>
        </collision>
        <inertial>
            <mass value="0.027309" />
            <origin xyz="0.0 0.0 0.0" rpy="0 0 0" />
            <inertia ixx="0.000003" ixy="-0.000002" ixz="0.000000" iyx="-0.000002" iyy="0.000021" iyz="0.000000" izx="0.000000" izy="0.000000" izz="0.000020" />
        </inertial>
    </link>
    <joint name="robotiq_85_left_inner_knuckle_joint" type="fixed">
        <parent link="robotiq_85_base_link" />
        <child link="robotiq_85_left_inner_knuckle_link" />
        <axis xyz="0 0 1" />
        <origin rpy="3.141592653589793 0.0 0.0" xyz="0.06142 0.0127 0" />
        <limit effort="0.1" lower="-3.14" upper="3.14" velocity="100.0" />
        <!-- <mimic joint="${prefix}robotiq_85_left_knuckle_joint" offset="0"/> -->
    </joint>
    <joint name="robotiq_85_right_inner_knuckle_joint" type="fixed">
        <parent link="robotiq_85_base_link" />
        <child link="robotiq_85_right_inner_knuckle_link" />
        <axis xyz="0 0 1" />
        <origin rpy="0 0 0" xyz="0.06142 -0.0127 0" />
        <limit effort="0.1" lower="-3.14" upper="3.14" velocity="100.0" />
        <!-- <mimic joint="${prefix}robotiq_85_left_knuckle_joint" offset="0"/> -->
    </joint>
    <link name="robotiq_85_left_inner_knuckle_link">
        <visual>
            <geometry>
                <mesh filename="package://robotiq_description/meshes/visual/robotiq_85_inner_knuckle_link.dae" />
            </geometry>
        </visual>
        <collision>
            <geometry>
                <mesh filename="package://robotiq_description/meshes/collision/robotiq_85_inner_knuckle_link.stl" />
            </geometry>
        </collision>
        <inertial>
            <mass value="0.029951" />
            <origin xyz="0.0 0.0 0.0" rpy="0 0 0" />
            <inertia ixx="0.000039" ixy="0.000000" ixz="0.000000" iyx="0.000000" iyy="0.000005" iyz="0.000000" izx="0.000000" izy="0.000000" izz="0.000035" />
        </inertial>
    </link>
    <link name="robotiq_85_right_inner_knuckle_link">
        <visual>
            <geometry>
                <mesh filename="package://robotiq_description/meshes/visual/robotiq_85_inner_knuckle_link.dae" />
            </geometry>
        </visual>
        <collision>
            <geometry>
                <mesh filename="package://robotiq_description/meshes/collision/robotiq_85_inner_knuckle_link.stl" />
            </geometry>
        </collision>
        <inertial>
            <mass value="0.029951" />
            <origin xyz="0.0 0.0 0.0" rpy="0 0 0" />
            <inertia ixx="0.000039" ixy="0.000000" ixz="0.000000" iyx="0.000000" iyy="0.000005" iyz="0.000000" izx="0.000000" izy="0.000000" izz="0.000035" />
        </inertial>
    </link>
    <joint name="robotiq_85_left_finger_tip_joint" type="fixed">
        <parent link="robotiq_85_left_inner_knuckle_link" />
        <child link="robotiq_85_left_finger_tip_link" />
        <axis xyz="0 0 1" />
        <origin rpy="0.0 0.0 0.0" xyz="0.04303959807 -0.03759940821 0.0" />
        <limit effort="0.1" lower="-3.14" upper="3.14" velocity="100.0" />
        <!-- <mimic joint="${prefix}robotiq_85_left_knuckle_joint" multiplier="-1"/> -->
    </joint>
    <joint name="robotiq_85_right_finger_tip_joint" type="fixed">
        <parent link="robotiq_85_right_inner_knuckle_link" />
        <child link="robotiq_85_right_finger_tip_link" />
        <axis xyz="0 0 1" />
        <origin rpy="0.0 0.0 0.0" xyz="0.04303959807 -0.03759940821  0.0" />
        <limit effort="0.1" lower="-3.14" upper="3.14" velocity="100.0" />
        <!-- <mimic joint="${prefix}robotiq_85_left_knuckle_joint" multiplier="-1"/> -->
    </joint>
    <link name="robotiq_85_left_finger_tip_link">
        <visual>
            <geometry>
                <mesh filename="package://robotiq_description/meshes/visual/robotiq_85_finger_tip_link.dae" />
            </geometry>
        </visual>
        <collision>
            <geometry>
                <mesh filename="package://robotiq_description/meshes/collision/robotiq_85_finger_tip_link.stl" />
            </geometry>
        </collision>
        <inertial>
            <mass value="0.019555" />
            <origin xyz="0.0 0.0 0.0" rpy="0 0 0" />
            <inertia ixx="0.000002" ixy="0.000000" ixz="0.000000" iyx="0.000000" iyy="0.000005" iyz="0.000000" izx="0.000000" izy="0.000000" izz="0.000006" />
        </inertial>
    </link>
    <link name="robotiq_85_right_finger_tip_link">
        <visual>
            <geometry>
                <mesh filename="package://robotiq_description/meshes/visual/robotiq_85_finger_tip_link.dae" />
            </geometry>
        </visual>
        <collision>
            <geometry>
                <mesh filename="package://robotiq_description/meshes/collision/robotiq_85_finger_tip_link.stl" />
            </geometry>
        </collision>
        <inertial>
            <mass value="0.019555" />
            <origin xyz="0.0 0.0 0.0" rpy="0 0 0" />
            <inertia ixx="0.000002" ixy="0.000000" ixz="0.000000" iyx="0.000000" iyy="0.000005" iyz="0.000000" izx="0.000000" izy="0.000000" izz="0.000006" />
        </inertial>
    </link>
    <!-- Improve grasping physics -->
    <gazebo reference="robotiq_85_left_finger_tip_link">
        <kp>1000000.0</kp>
        <kd>1.0</kd>
        <mu1>1.0</mu1>
        <mu2>1.0</mu2>
        <minDepth>0.001</minDepth>
    </gazebo>
    <gazebo reference="robotiq_85_right_finger_tip_link">
        <kp>1000000.0</kp>
        <kd>1.0</kd>
        <mu1>1.0</mu1>
        <mu2>1.0</mu2>
        <minDepth>0.001</minDepth>
    </gazebo>
    <transmission name="robotiq_85_left_knuckle_trans">
        <type>transmission_interface/SimpleTransmission</type>
        <joint name="robotiq_85_left_knuckle_joint">
            <hardwareInterface>PositionJointInterface</hardwareInterface>
            <!-- <hardwareInterface>EffortJointInterface</hardwareInterface> -->
        </joint>
        <actuator name="robotiq_85_left_knuckle_motor">
            <mechanicalReduction>1</mechanicalReduction>
            <hardwareInterface>PositionJointInterface</hardwareInterface>
            <!-- <hardwareInterface>EfforJointInterface</hardwareInterface> -->
        </actuator>
    </transmission>
    <!-- Mimic joints -->
    <gazebo>
        <plugin filename="libgazebo_mimic_joint_plugin.so" name="mimic_robotiq_85_1">
            <joint>robotiq_85_left_knuckle_joint</joint>
            <mimicJoint>robotiq_85_right_knuckle_joint</mimicJoint>
        </plugin>
        <plugin filename="libgazebo_mimic_joint_plugin.so" name="mimic_robotiq_85_2">
            <joint>robotiq_85_left_knuckle_joint</joint>
            <mimicJoint>robotiq_85_left_inner_knuckle_joint</mimicJoint>
        </plugin>
        <plugin filename="libgazebo_mimic_joint_plugin.so" name="mimic_robotiq_85_3">
            <joint>robotiq_85_left_knuckle_joint</joint>
            <mimicJoint>robotiq_85_right_inner_knuckle_joint</mimicJoint>
        </plugin>
        <plugin filename="libgazebo_mimic_joint_plugin.so" name="mimic_robotiq_85_4">
            <joint>robotiq_85_left_knuckle_joint</joint>
            <mimicJoint>robotiq_85_left_finger_tip_joint</mimicJoint>
            <multiplier>-1.0</multiplier>
            <offset>0.0</offset>
        </plugin>
        <plugin filename="libgazebo_mimic_joint_plugin.so" name="mimic_robotiq_85_5">
            <joint>robotiq_85_left_knuckle_joint</joint>
            <mimicJoint>robotiq_85_right_finger_tip_joint</mimicJoint>
            <multiplier>-1.0</multiplier>
            <offset>0.0</offset>
        </plugin>
    </gazebo>
    <!-- camera body, with origin at bottom screw mount -->
    <joint name="camera_1_joint" type="fixed">
        <origin rpy="0 0 0" xyz="0 0 0" />
        <parent link="to_d435_link" />
        <child link="camera_1_bottom_screw_frame" />
    </joint>
    <link name="camera_1_bottom_screw_frame" />
    <joint name="camera_1_link_joint" type="fixed">
        <origin rpy="0 0 0" xyz="0.010600000000000002 0.0175 0.0125" />
        <parent link="camera_1_bottom_screw_frame" />
        <child link="camera_1_link" />
    </joint>
    <link name="camera_1_link">
        <visual>
            <!-- the mesh origin is at front plate in between the two infrared camera axes -->
            <origin rpy="1.5707963267948966 0 1.5707963267948966" xyz="0.0043 -0.0175 0" />
            <geometry>
                <!-- <box size="${d435_cam_width} ${d435_cam_height} ${d435_cam_depth}"/> -->
                <mesh filename="package://realsense2_description/meshes/d435.dae" />
            </geometry>
        </visual>
        <collision>
            <origin rpy="0 0 0" xyz="0 -0.0175 0" />
            <geometry>
                <box size="0.02505 0.09 0.025" />
            </geometry>
        </collision>
        <inertial>
            <!-- The following are not reliable values, and should not be used for modeling -->
            <mass value="0.072" />
            <origin xyz="0 0 0" rpy="0 0 0" />
            <inertia ixx="0.003881243" ixy="0.0" ixz="0.0" iyy="0.000498940" iyz="0.0" izz="0.003879257" />
        </inertial>
    </link>
    <joint name="connector_base_joint" type="fixed">
        <parent link="robotiq_85_base_link" />
        <child link="connector_base_link" />
        <origin rpy="0 0 0" xyz="0.0365 0 0.028" />
        <!--origin
            xyz="0 0 0" rpy="0 0 0"/-->
    </joint>
    <link name="connector_base_link">
        <inertial>
            <origin rpy="0 0 0" xyz="0.00434937212978377 5.20417042793042E-18 0.0334255512696373" />
            <mass value="0.00891029041853838" />
            <inertia ixx="3.67875098397923E-06" ixy="9.3727693696127E-22" ixz="-1.4437922233958E-07" iyy="3.27524790321564E-06" iyz="-1.30347421081159E-21" izz="8.06494585207849E-07" />
        </inertial>
        <visual>
            <origin rpy="0 0 0" xyz="0 0 0" />
            <geometry>
                <mesh filename="package://connector_description/meshes/base_link.STL" />
            </geometry>
            <material name="">
                <color rgba="1 1 1 1" />
            </material>
        </visual>
        <collision>
            <origin rpy="0 0 0" xyz="0 0 0" />
            <geometry>
                <mesh filename="package://connector_description/meshes/base_link.STL" />
            </geometry>
        </collision>
    </link>
    <link name="to_d435_link" />
    <joint name="to_d435_joint" type="fixed">
        <origin rpy="0 0 0" xyz="0.0152 0 0.0445" />
        <parent link="connector_base_link" />
        <child link="to_d435_link" />
        <axis xyz="0 0 0" />
    </joint>
</robot>

